Traceback (most recent call last):
  File "/opt/anaconda3/lib/python3.7/site-packages/jupyter_cache/executors/utils.py", line 56, in single_nb_execution
    record_timing=False,
  File "/opt/anaconda3/lib/python3.7/site-packages/nbclient/client.py", line 1112, in execute
    return NotebookClient(nb=nb, resources=resources, km=km, **kwargs).execute()
  File "/opt/anaconda3/lib/python3.7/site-packages/nbclient/util.py", line 74, in wrapped
    return just_run(coro(*args, **kwargs))
  File "/opt/anaconda3/lib/python3.7/site-packages/nbclient/util.py", line 53, in just_run
    return loop.run_until_complete(coro)
  File "/opt/anaconda3/lib/python3.7/asyncio/base_events.py", line 587, in run_until_complete
    return future.result()
  File "/opt/anaconda3/lib/python3.7/site-packages/nbclient/client.py", line 554, in async_execute
    cell, index, execution_count=self.code_cells_executed + 1
  File "/opt/anaconda3/lib/python3.7/site-packages/nbclient/client.py", line 857, in async_execute_cell
    self._check_raise_for_error(cell, exec_reply)
  File "/opt/anaconda3/lib/python3.7/site-packages/nbclient/client.py", line 760, in _check_raise_for_error
    raise CellExecutionError.from_cell_and_msg(cell, exec_reply_content)
nbclient.exceptions.CellExecutionError: An error occurred while executing the following cell:
------------------
library(haven)

read_sas(
  unzip(
    temp, 
    "pcen_v2018_y1018.sas7bdat/pcen_v2018_y1018.sas7bdat"
    )
  ) -> oursasdata
------------------

Error: `file` must be a string, raw vector or a connection.
Traceback:

1. read_sas(unzip(temp, "pcen_v2018_y1018.sas7bdat/pcen_v2018_y1018.sas7bdat"))
2. readr::datasource(data_file)
3. stop("`file` must be a string, raw vector or a connection.", 
 .     call. = FALSE)
ERROR: Error: `file` must be a string, raw vector or a connection.


